/home/zihan/anaconda3/envs/x/lib/python3.7/site-packages/numpy/core/fromnumeric.py:3441: RuntimeWarning: Mean of empty slice.
  out=out, **kwargs)
/home/zihan/anaconda3/envs/x/lib/python3.7/site-packages/numpy/core/_methods.py:189: RuntimeWarning: invalid value encountered in double_scalars
  ret = ret.dtype.type(ret / rcount)
pygame 2.0.0 (SDL 2.0.12, python 3.7.10)
Hello from the pygame community. https://www.pygame.org/contribute.html
boxing_v1 pettingzoo
Load boxing_v1 environment in type pettingzoo.
Env observation space: Box(0.0, 1.0, (130,), float32) action space: Discrete(18)
<env.wrappers.mars_wrappers.Dict2TupleWrapper object at 0x7f0e9224f9d0>
Agents No. [1] (index starting from 0) are not learnable.
Arguments:  {'env_name': 'boxing_v1', 'env_type': 'pettingzoo', 'num_envs': 1, 'ram': True, 'seed': 1122, 'algorithm': 'DQN', 'algorithm_spec': {'episodic_update': False, 'dueling': False, 'replay_buffer_size': '1e5', 'gamma': 0.99, 'multi_step': 1, 'target_update_interval': 1000, 'eps_start': 1.0, 'eps_final': 0.01, 'eps_decay': 30000}, 'batch_size': 32, 'max_episodes': 30000, 'max_steps_per_episode': 10000, 'train_start_frame': 0, 'optimizer': 'adam', 'learning_rate': '1e-4', 'device': 'gpu', 'update_itr': 1, 'log_avg_window': 20, 'log_interval': 20, 'render': False, 'test': False, 'exploit': False, 'load_model_idx': False, 'load_model_full_path': False, 'save_path': '', 'save_interval': 2000, 'net_architecture': {'hidden_dim_list': [64, 64, 64], 'hidden_activation': 'ReLU', 'output_activation': False}, 'marl_method': 'fictitious_selfplay', 'marl_spec': {'min_update_interval': 20, 'score_avg_window': 10, 'selfplay_score_delta': 60, 'trainable_agent_idx': 0, 'opponent_idx': 1}}
Save models to : /home/zihan/research/MARS/data/model/20211107214200/pettingzoo_boxingv1_fictitious_selfplay_dqn. 
 Save logs to: /home/zihan/research/MARS/data/log/20211107214200/pettingzoo_boxingv1_fictitious_selfplay_dqn.
Episode: 1, avg. length 1784.0
first_0:                 episode reward: 4.0000,                 loss: 0.0320
second_0:                 episode reward: -4.0000,                 loss: nan
Episode: 21, avg. length 1784.0
first_0:                 episode reward: 5.1000,                 loss: 0.0148
second_0:                 episode reward: -5.1000,                 loss: nan
Episode: 41, avg. length 1784.0
first_0:                 episode reward: 7.4000,                 loss: 0.0159
second_0:                 episode reward: -7.4000,                 loss: nan
Episode: 61, avg. length 1784.0
first_0:                 episode reward: 8.3500,                 loss: 0.0225
second_0:                 episode reward: -8.3500,                 loss: nan
Episode: 81, avg. length 1784.0
first_0:                 episode reward: 11.8000,                 loss: 0.0227
second_0:                 episode reward: -11.8000,                 loss: nan
Episode: 101, avg. length 1784.0
first_0:                 episode reward: 12.8000,                 loss: 0.0281
second_0:                 episode reward: -12.8000,                 loss: nan
Traceback (most recent call last):
  File "run.py", line 45, in <module>
    rollout(env, model, args, save_id)
  File "/home/zihan/research/MARS/mars_core/rollout.py", line 19, in rollout
    rollout_normal(env, model, save_id, args)
  File "/home/zihan/research/MARS/mars_core/rollout.py", line 125, in rollout_normal
    model, logger, env, args
  File "/home/zihan/research/MARS/mars_core/marl/selfplay.py", line 107, in step
    model.agents[self.current_learnable_model_idx].reinit(nets_init=False, buffer_init=True, schedulers_init=True)  # reinitialize the model
AttributeError: 'FictitiousSelfPlayMetaLearner' object has no attribute 'current_learnable_model_idx'
